Workbook

Sheet INSTRUCCIONES
A1: PAQUETE 01 — CIERRE MP-03
A2: Guía offline. No habilita pose, torreta, shooter, feeder, intake ni drivetrain.
A4: ORDEN OBLIGATORIO
A5: 1 | B5: Confirmar área despejada, mecanismos sin piezas y Stop accesible.
A6: 2 | B6: Completar SESION y MP03_01_Config antes de INIT.
A7: 3 | B7: Ejecutar cinco ciclos con el mismo APK.
A8: 4 | B8: Registrar tags 20/24 y pose 3D.
A9: 5 | B9: Ejecutar todos los fallos sin movimiento.
A10: 6 | B10: Registrar poses estáticas medidas.
A11: 7 | B11: Revisar DASHBOARD; no editar fórmulas.
A12: 8 | B12: Guardar con sufijo _FILLED y devolver sin borrar columnas.
A14: ABORTAR DE INMEDIATO
A15: Movimiento de cualquier actuador | B15: STOP/E-stop, ABORTED y evidencia.
A16: Humo, olor, calor, ruido o cable suelto | B16: Cortar energía; no reconectar.
A17: Excepción/reinicio inesperado | B17: STOP; registrar mensaje y APK SHA.
A18: Pipeline/map/extrínseca distinta | B18: Detener pose 3D y crear ConfigRevision.
A20: SHOT_DATASET — preparado para sesiones futuras; MP-03 no autoriza tiros.

Sheet SESION
A1: IDENTIDAD DE SESIÓN
A2: Completar antes de abrir el OpMode. Amarillo = entrada.
A4: Campo | B4: Valor | C4: Guía | D4: Obligatorio
A5: SchemaVersion | B5: 1 | C5: Fijo
A6: TemplateVersion | B6: 1 | C6: Fijo
A7: PacketId | B7: 01-cierre-mp03 | C7: Fijo
A8: PacketVersion | B8: 1 | C8: Fijo
A9: SessionId | C9: Ej. MP03-20260722-A | D9: REQUIRED
A10: Fecha local | C10: YYYY-MM-DD | D10: REQUIRED
A11: Hora inicio | C11: HH:MM | D11: REQUIRED
A12: Ubicación | D12: REQUIRED
A13: Operador | D13: REQUIRED
A14: Test lead | D14: REQUIRED
A15: Safety observer | D15: REQUIRED
A16: Data recorder | D16: REQUIRED
A17: Git commit | C17: SHA inequívoco | D17: REQUIRED
A18: APK SHA-256 | C18: 64 hex | D18: REQUIRED
A19: ConfigRevision | B19: R1 | C19: Incrementar tras cambio material | D19: REQUIRED
A20: Robot config | C20: Nombre/revisión RC | D20: REQUIRED
A21: Batería ID | D21: REQUIRED
A22: Voltaje inicial (V) | C22: Número | D22: REQUIRED
A23: Pipeline SHA-256 | B23: 0B954CFA8641B460C13E8DF65A7A4691E7FD409821A09A008BF3ADA141D20693 | C23: Actualizar si cambia | D23: REQUIRED
A24: Field map SHA-256 | C24: Pendiente | D24: REQUIRED
A25: Condición de luz
A26: Notas

Sheet CAMBIOS
A1: REGISTRO DE CAMBIOS
A2: No mezclar intentos de distintas ConfigRevision.
A4: ChangeId | B4: TimestampLocal | C4: FromRevision | D4: ToRevision | E4: Category | F4: Before | G4: After | H4: AppliesFromAttemptId | I4: Reason
A5: CHG-01
A6: CHG-02
A7: CHG-03
A8: CHG-04
A9: CHG-05
A10: CHG-06
A11: CHG-07
A12: CHG-08
A13: CHG-09
A14: CHG-10
A15: CHG-11
A16: CHG-12
... A34: CHG-30

Sheet CONFIG
A1: CONSTANTES DEL PAQUETE
A2: Editar sólo mediante TemplateVersion o ConfigRevision documentada.
A4: Key | B4: Value | C4: Unit | D4: Source | E4: Purpose
A5: LIMELIGHT_MAX_STALENESS_MS | B5: 200 | C5: ms | D5: LowAltitudeConstants.VisionConstants | E5: Gate visual
A6: EXPECTED_PIPELINE | B6: 0 | C6: index | D6: LowAltitudeConstants.VisionConstants | E6: Pipeline AprilTag
A7: BLUE_GOAL_TAG_ID | B7: 20 | C7: id | D7: LowAltitudeConstants.TurretConstants | E7: Goal azul
A8: RED_GOAL_TAG_ID | B8: 24 | C8: id | D8: LowAltitudeConstants.TurretConstants | E8: Goal rojo
A9: MARKER_BLACK_SIZE_MM | B9: 165.1 | C9: mm | D9: mp03-limelight-commissioning.md | E9: Cuadrado negro oficial
A10: EXPECTED_LIFECYCLE_CYCLES | B10: 5 | C10: count | D10: Gate MP-03 | E10: Mismo APK
A11: SHOOTER_READY_ERROR_RPM | B11: 100 | C11: RPM | D11: T8.1 | E11: Dataset futuro
A12: SHOOTER_READY_DWELL_MS | B12: 250 | C12: ms | D12: T8.1 | E12: Dataset futuro

Sheet CATALOGOS
A1: CATÁLOGOS
A2: Valores válidos para dropdowns y exports.
A4: Status | C4: YesNo | E4: Quality | G4: ModelKind | I4: Role | K4: Outcome
A5: NOT_RUN | C5: YES | E5: VALID | G5: LINEAR | I5: CALIBRATION | K5: SCORED
A6: IN_PROGRESS | C6: NO | E6: NO_TARGET | G6: QUADRATIC | I6: HOLDOUT | K6: SHORT
A7: PASS | E7: WRONG_TAG | G7: PIECEWISE | K7: LONG
A8: FAIL | E8: STALE | K8: REBOUND
A9: BLOCKED | E9: PIPELINE_MISMATCH | K9: OTHER
A10: ABORTED | E10: DEVICE_DISCONNECTED
A11: INVALID_DATA | E11: INVALID
A12: NOT_APPLICABLE

Sheet MP03_01_Config
A1: MP03.1 — CONFIGURACIÓN
A2: Completar antes de lifecycle.
A4: TestId | B4: Item | C4: Expected | D4: Observed | E4: EvidenceRef | F4: Status | G4: AbortReason | H4: Notes
A5: CFG-01 | B5: Mapping RC | C5: limelight | D5: limelight | F5: NOT_RUN
A6: CFG-02 | B6: Firmware/UI | C6: 2026 | D6: 2026 | F6: NOT_RUN
A7: CFG-03 | B7: Pipeline index | C7: 0 | D7: 0 | F7: NOT_RUN
A8: CFG-04 | B8: Resolución/FPS | C8: 640x480 / 90 | D8: 640x480 / 90 | F8: NOT_RUN
A9: CFG-05 | B9: Tag family | C9: AprilTag Classic 36h11 | D9: AprilTag Classic 36h11 | F9: NOT_RUN
A10: CFG-06 | B10: Marker black size | C10: 165.1 mm | D10: 165.1 mm | F10: NOT_RUN | H10: No validar escala con tag 160 mm
A11: CFG-07 | B11: fiducial_skip3d | C11: 0 | F11: NOT_RUN | H11: Debe habilitar pose 3D
A12: CFG-08 | B12: Field map export/hash | C12: Presente + SHA-256 | F12: NOT_RUN | H12: Pendiente
A13: CFG-09 | B13: Extrínseca activa | C13: 30 deg, yaw=0, roll=0 | F13: NOT_RUN | H13: Usar geometria-robot-mp04.md
A14: CFG-10 | B14: Montaje rígido | C14: YES | F14: NOT_RUN
A15: CFG-11 | B15: Oclusión en posiciones de prueba | C15: NO | F15: NOT_RUN
A16: CFG-12 | B16: Tag azul 20 disponible | C16: YES | F16: NOT_RUN
A17: CFG-13 | B17: Tag rojo 24 disponible | C17: YES | F17: NOT_RUN
A18: CFG-14 | B18: Sin consumidores de actuadores | C18: YES | F18: NOT_RUN | H18: Revisión humana

Sheet MP03_02_Lifecycle
A1: MP03.2 — CINCO CICLOS
A2: Mismo APK. Movimiento o excepción aborta.
A4: TestId | B4: Cycle | C4: ConfigRevision | D4: Init | E4: Start | F4: Stop | G4: Connected | H4: PipelineObserved | I4: Exception | J4: ResourceOpenAfterStop | K4: AnyMovement | L4: EvidenceRef | M4: Status | N4: Notes
A5: LIFE-1 | B5: 1 | C5: R1 | M5: =IF(COUNTA(D5:K5)=0,"NOT_RUN",IF(OR(K5="YES",I5="YES",J5="YES"),"FAIL",IF(AND(D5="YES",E5="YES",F5="YES",G5="YES",H5=0,I5="NO",J5="NO",K5="NO"),"PASS","BLOCKED"))) -> NOT_RUN
A6: LIFE-2 | B6: 2 | C6: R1 | M6: =IF(COUNTA(D6:K6)=0,"NOT_RUN",IF(OR(K6="YES",I6="YES",J6="YES"),"FAIL",IF(AND(D6="YES",E6="YES",F6="YES",G6="YES",H6=0,I6="NO",J6="NO",K6="NO"),"PASS","BLOCKED"))) -> NOT_RUN
A7: LIFE-3 | B7: 3 | C7: R1 | M7: =IF(COUNTA(D7:K7)=0,"NOT_RUN",IF(OR(K7="YES",I7="YES",J7="YES"),"FAIL",IF(AND(D7="YES",E7="YES",F7="YES",G7="YES",H7=0,I7="NO",J7="NO",K7="NO"),"PASS","BLOCKED"))) -> NOT_RUN
A8: LIFE-4 | B8: 4 | C8: R1 | M8: =IF(COUNTA(D8:K8)=0,"NOT_RUN",IF(OR(K8="YES",I8="YES",J8="YES"),"FAIL",IF(AND(D8="YES",E8="YES",F8="YES",G8="YES",H8=0,I8="NO",J8="NO",K8="NO"),"PASS","BLOCKED"))) -> NOT_RUN
A9: LIFE-5 | B9: 5 | C9: R1 | M9: =IF(COUNTA(D9:K9)=0,"NOT_RUN",IF(OR(K9="YES",I9="YES",J9="YES"),"FAIL",IF(AND(D9="YES",E9="YES",F9="YES",G9="YES",H9=0,I9="NO",J9="NO",K9="NO"),"PASS","BLOCKED"))) -> NOT_RUN

Sheet MP03_03_Tags
A1: MP03.3 — TAGS Y POSE 3D
A2: Una fila por observación nueva; no promediar a mano.
A4: AttemptId | B4: ConfigRevision | C4: TagId | D4: Alliance | E4: ExpectedTag | F4: TxDeg | G4: TyDeg | H4: AreaPct | I4: StalenessMs | J4: TargetLatencyMs | K4: CaptureLatencyMs | L4: TotalLatencyMs | M4: TagCount | N4: BotPoseAvailable | O4: BotX | P4: BotY | Q4: BotZ | R4: BotYawDeg | S4: Finite | T4: Quality | U4: RejectionReason | V4: EvidenceRef
A5: TAG-01 | B5: R1
A6: TAG-02 | B6: R1
A7: TAG-03 | B7: R1
A8: TAG-04 | B8: R1
A9: TAG-05 | B9: R1
A10: TAG-06 | B10: R1
A11: TAG-07 | B11: R1
A12: TAG-08 | B12: R1
A13: TAG-09 | B13: R1
A14: TAG-10 | B14: R1
A15: TAG-11 | B15: R1
A16: TAG-12 | B16: R1
... A44: TAG-40 | B44: R1

Sheet MP03_04_Faults
A1: MP03.4 — FALLOS Y RECUPERACIÓN
A2: Todos mantienen actuadores inmóviles.
A4: TestId | B4: Case | C4: ExpectedQuality | D4: ObservedQuality | E4: ActionableValuesZero | F4: AnyMovement | G4: Exception | H4: Recovered | I4: EvidenceRef | J4: Status | K4: AbortReason | L4: Notes
A5: FLT-01 | B5: Camera covered | C5: NO_TARGET or STALE | J5: =IF(COUNTA(D5:I5)=0,"NOT_RUN",IF(OR(E5<>"YES",F5<>"NO",G5<>"NO"),"FAIL",IF(AND(D5<>"",H5="YES",I5<>""),"PASS","BLOCKED"))) -> NOT_RUN
A6: FLT-02 | B6: Wrong tag | C6: WRONG_TAG | J6: =IF(COUNTA(D6:I6)=0,"NOT_RUN",IF(OR(E6<>"YES",F6<>"NO",G6<>"NO"),"FAIL",IF(AND(D6<>"",H6="YES",I6<>""),"PASS","BLOCKED"))) -> NOT_RUN
A7: FLT-03 | B7: Invalid result | C7: INVALID | J7: =IF(COUNTA(D7:I7)=0,"NOT_RUN",IF(OR(E7<>"YES",F7<>"NO",G7<>"NO"),"FAIL",IF(AND(D7<>"",H7="YES",I7<>""),"PASS","BLOCKED"))) -> NOT_RUN
A8: FLT-04 | B8: Wrong pipeline | C8: PIPELINE_MISMATCH | J8: =IF(COUNTA(D8:I8)=0,"NOT_RUN",IF(OR(E8<>"YES",F8<>"NO",G8<>"NO"),"FAIL",IF(AND(D8<>"",H8="YES",I8<>""),"PASS","BLOCKED"))) -> NOT_RUN
A9: FLT-05 | B9: Disconnect | C9: DEVICE_DISCONNECTED | J9: =IF(COUNTA(D9:I9)=0,"NOT_RUN",IF(OR(E9<>"YES",F9<>"NO",G9<>"NO"),"FAIL",IF(AND(D9<>"",H9="YES",I9<>""),"PASS","BLOCKED"))) -> NOT_RUN
A10: FLT-06 | B10: Reconnect | C10: Telemetry only recovery | J10: =IF(COUNTA(D10:I10)=0,"NOT_RUN",IF(OR(E10<>"YES",F10<>"NO",G10<>"NO"),"FAIL",IF(AND(D10<>"",H10="YES",I10<>""),"PASS","BLOCKED"))) -> NOT_RUN
A11: FLT-07 | B11: Stale frame | C11: STALE | J11: =IF(COUNTA(D11:I11)=0,"NOT_RUN",IF(OR(E11<>"YES",F11<>"NO",G11<>"NO"),"FAIL",IF(AND(D11<>"",H11="YES",I11<>""),"PASS","BLOCKED"))) -> NOT_RUN
A12: FLT-08 | B12: No 3D pose | C12: Rejected / no actionable pose | J12: =IF(COUNTA(D12:I12)=0,"NOT_RUN",IF(OR(E12<>"YES",F12<>"NO",G12<>"NO"),"FAIL",IF(AND(D12<>"",H12="YES",I12<>""),"PASS","BLOCKED"))) -> NOT_RUN

Sheet MP03_05_StaticPose
A1: MP03.5 — POSE ESTÁTICA DIAGNÓSTICA
A2: No aplica corrección. Registrar marco y unidades.
A4: AttemptId | B4: ConfigRevision | C4: TagId | D4: PhysicalXIn | E4: PhysicalYIn | F4: PhysicalHeadingDeg | G4: LimelightXIn | H4: LimelightYIn | I4: LimelightHeadingDeg | J4: ResidualXIn | K4: ResidualYIn | L4: ResidualDistanceIn | M4: ResidualHeadingDeg | N4: StalenessMs | O4: EvidenceRef | P4: Status | Q4: Notes
A5: POSE-01 | B5: R1 | J5: =IF(OR(D5="",G5=""),"",G5-D5) | K5: =IF(OR(E5="",H5=""),"",H5-E5) | L5: =IF(OR(J5="",K5=""),"",SQRT(J5^2+K5^2)) | M5: =IF(OR(F5="",I5=""),"",MOD(I5-F5+180,360)-180) | P5: NOT_RUN
A6: POSE-02 | B6: R1 | J6: =IF(OR(D6="",G6=""),"",G6-D6) | K6: =IF(OR(E6="",H6=""),"",H6-E6) | L6: =IF(OR(J6="",K6=""),"",SQRT(J6^2+K6^2)) | M6: =IF(OR(F6="",I6=""),"",MOD(I6-F6+180,360)-180) | P6: NOT_RUN
A7: POSE-03 | B7: R1 | J7: =IF(OR(D7="",G7=""),"",G7-D7) | K7: =IF(OR(E7="",H7=""),"",H7-E7) | L7: =IF(OR(J7="",K7=""),"",SQRT(J7^2+K7^2)) | M7: =IF(OR(F7="",I7=""),"",MOD(I7-F7+180,360)-180) | P7: NOT_RUN
A8: POSE-04 | B8: R1 | J8: =IF(OR(D8="",G8=""),"",G8-D8) | K8: =IF(OR(E8="",H8=""),"",H8-E8) | L8: =IF(OR(J8="",K8=""),"",SQRT(J8^2+K8^2)) | M8: =IF(OR(F8="",I8=""),"",MOD(I8-F8+180,360)-180) | P8: NOT_RUN
A9: POSE-05 | B9: R1 | J9: =IF(OR(D9="",G9=""),"",G9-D9) | K9: =IF(OR(E9="",H9=""),"",H9-E9) | L9: =IF(OR(J9="",K9=""),"",SQRT(J9^2+K9^2)) | M9: =IF(OR(F9="",I9=""),"",MOD(I9-F9+180,360)-180) | P9: NOT_RUN
A10: POSE-06 | B10: R1 | J10: =IF(OR(D10="",G10=""),"",G10-D10) | K10: =IF(OR(E10="",H10=""),"",H10-E10) | L10: =IF(OR(J10="",K10=""),"",SQRT(J10^2+K10^2)) | M10: =IF(OR(F10="",I10=""),"",MOD(I10-F10+180,360)-180) | P10: NOT_RUN
A11: POSE-07 | B11: R1 | J11: =IF(OR(D11="",G11=""),"",G11-D11) | K11: =IF(OR(E11="",H11=""),"",H11-E11) | L11: =IF(OR(J11="",K11=""),"",SQRT(J11^2+K11^2)) | M11: =IF(OR(F11="",I11=""),"",MOD(I11-F11+180,360)-180) | P11: NOT_RUN
A12: POSE-08 | B12: R1 | J12: =IF(OR(D12="",G12=""),"",G12-D12) | K12: =IF(OR(E12="",H12=""),"",H12-E12) | L12: =IF(OR(J12="",K12=""),"",SQRT(J12^2+K12^2)) | M12: =IF(OR(F12="",I12=""),"",MOD(I12-F12+180,360)-180) | P12: NOT_RUN
A13: POSE-09 | B13: R1 | J13: =IF(OR(D13="",G13=""),"",G13-D13) | K13: =IF(OR(E13="",H13=""),"",H13-E13) | L13: =IF(OR(J13="",K13=""),"",SQRT(J13^2+K13^2)) | M13: =IF(OR(F13="",I13=""),"",MOD(I13-F13+180,360)-180) | P13: NOT_RUN
A14: POSE-10 | B14: R1 | J14: =IF(OR(D14="",G14=""),"",G14-D14) | K14: =IF(OR(E14="",H14=""),"",H14-E14) | L14: =IF(OR(J14="",K14=""),"",SQRT(J14^2+K14^2)) | M14: =IF(OR(F14="",I14=""),"",MOD(I14-F14+180,360)-180) | P14: NOT_RUN
A15: POSE-11 | B15: R1 | J15: =IF(OR(D15="",G15=""),"",G15-D15) | K15: =IF(OR(E15="",H15=""),"",H15-E15) | L15: =IF(OR(J15="",K15=""),"",SQRT(J15^2+K15^2)) | M15: =IF(OR(F15="",I15=""),"",MOD(I15-F15+180,360)-180) | P15: NOT_RUN
A16: POSE-12 | B16: R1 | J16: =IF(OR(D16="",G16=""),"",G16-D16) | K16: =IF(OR(E16="",H16=""),"",H16-E16) | L16: =IF(OR(J16="",K16=""),"",SQRT(J16^2+K16^2)) | M16: =IF(OR(F16="",I16=""),"",MOD(I16-F16+180,360)-180) | P16: NOT_RUN
... A24: POSE-20 | B24: R1 | J24: =IF(OR(D24="",G24=""),"",G24-D24) | K24: =IF(OR(E24="",H24=""),"",H24-E24) | L24: =IF(OR(J24="",K24=""),"",SQRT(J24^2+K24^2)) | M24: =IF(OR(F24="",I24=""),"",MOD(I24-F24+180,360)-180) | P24: NOT_RUN

Sheet SHOT_DATASET
A1: DATASET DE TIRO — EXTRA RPM/DISTANCIA
A2: Preparado para sesiones posteriores. MP-03 no autoriza tiros.
A4: sessionId | B4: distanceGroupId | C4: modelKind | D4: role | E4: distanceInches | F4: targetRpm | G4: measuredRpmAtFeed | H4: rpmReadyHoldMs | I4: outcome | J4: AttemptId | K4: ConfigRevision | L4: Position | M4: BatteryId | N4: FusedXIn | O4: FusedYIn | P4: FusedHeadingDeg | Q4: TurretErrorDeg | R4: ArtifactBatch | S4: EvidenceRef | T4: Notes | U4: RpmError | V4: ReadyGate
J5: SHOT-001 | K5: R1 | U5: =IF(OR(F5="",G5=""),"",ABS(G5-F5)) | V5: =IF(A5="","",IF(AND(U5<=CONFIG!B11,H5>=CONFIG!B12),"PASS","FAIL"))
J6: SHOT-002 | K6: R1 | U6: =IF(OR(F6="",G6=""),"",ABS(G6-F6)) | V6: =IF(A6="","",IF(AND(U6<=CONFIG!B11,H6>=CONFIG!B12),"PASS","FAIL"))
J7: SHOT-003 | K7: R1 | U7: =IF(OR(F7="",G7=""),"",ABS(G7-F7)) | V7: =IF(A7="","",IF(AND(U7<=CONFIG!B11,H7>=CONFIG!B12),"PASS","FAIL"))
J8: SHOT-004 | K8: R1 | U8: =IF(OR(F8="",G8=""),"",ABS(G8-F8)) | V8: =IF(A8="","",IF(AND(U8<=CONFIG!B11,H8>=CONFIG!B12),"PASS","FAIL"))
J9: SHOT-005 | K9: R1 | U9: =IF(OR(F9="",G9=""),"",ABS(G9-F9)) | V9: =IF(A9="","",IF(AND(U9<=CONFIG!B11,H9>=CONFIG!B12),"PASS","FAIL"))
J10: SHOT-006 | K10: R1 | U10: =IF(OR(F10="",G10=""),"",ABS(G10-F10)) | V10: =IF(A10="","",IF(AND(U10<=CONFIG!B11,H10>=CONFIG!B12),"PASS","FAIL"))
J11: SHOT-007 | K11: R1 | U11: =IF(OR(F11="",G11=""),"",ABS(G11-F11)) | V11: =IF(A11="","",IF(AND(U11<=CONFIG!B11,H11>=CONFIG!B12),"PASS","FAIL"))
J12: SHOT-008 | K12: R1 | U12: =IF(OR(F12="",G12=""),"",ABS(G12-F12)) | V12: =IF(A12="","",IF(AND(U12<=CONFIG!B11,H12>=CONFIG!B12),"PASS","FAIL"))
J13: SHOT-009 | K13: R1 | U13: =IF(OR(F13="",G13=""),"",ABS(G13-F13)) | V13: =IF(A13="","",IF(AND(U13<=CONFIG!B11,H13>=CONFIG!B12),"PASS","FAIL"))
J14: SHOT-010 | K14: R1 | U14: =IF(OR(F14="",G14=""),"",ABS(G14-F14)) | V14: =IF(A14="","",IF(AND(U14<=CONFIG!B11,H14>=CONFIG!B12),"PASS","FAIL"))
J15: SHOT-011 | K15: R1 | U15: =IF(OR(F15="",G15=""),"",ABS(G15-F15)) | V15: =IF(A15="","",IF(AND(U15<=CONFIG!B11,H15>=CONFIG!B12),"PASS","FAIL"))
J16: SHOT-012 | K16: R1 | U16: =IF(OR(F16="",G16=""),"",ABS(G16-F16)) | V16: =IF(A16="","",IF(AND(U16<=CONFIG!B11,H16>=CONFIG!B12),"PASS","FAIL"))
J17: SHOT-013 | K17: R1 | U17: =IF(OR(F17="",G17=""),"",ABS(G17-F17)) | V17: =IF(A17="","",IF(AND(U17<=CONFIG!B11,H17>=CONFIG!B12),"PASS","FAIL"))
J18: SHOT-014 | K18: R1 | U18: =IF(OR(F18="",G18=""),"",ABS(G18-F18)) | V18: =IF(A18="","",IF(AND(U18<=CONFIG!B11,H18>=CONFIG!B12),"PASS","FAIL"))
J19: SHOT-015 | K19: R1 | U19: =IF(OR(F19="",G19=""),"",ABS(G19-F19)) | V19: =IF(A19="","",IF(AND(U19<=CONFIG!B11,H19>=CONFIG!B12),"PASS","FAIL"))
J20: SHOT-016 | K20: R1 | U20: =IF(OR(F20="",G20=""),"",ABS(G20-F20)) | V20: =IF(A20="","",IF(AND(U20<=CONFIG!B11,H20>=CONFIG!B12),"PASS","FAIL"))
J21: SHOT-017 | K21: R1 | U21: =IF(OR(F21="",G21=""),"",ABS(G21-F21)) | V21: =IF(A21="","",IF(AND(U21<=CONFIG!B11,H21>=CONFIG!B12),"PASS","FAIL"))
J22: SHOT-018 | K22: R1 | U22: =IF(OR(F22="",G22=""),"",ABS(G22-F22)) | V22: =IF(A22="","",IF(AND(U22<=CONFIG!B11,H22>=CONFIG!B12),"PASS","FAIL"))
J23: SHOT-019 | K23: R1 | U23: =IF(OR(F23="",G23=""),"",ABS(G23-F23)) | V23: =IF(A23="","",IF(AND(U23<=CONFIG!B11,H23>=CONFIG!B12),"PASS","FAIL"))
J24: SHOT-020 | K24: R1 | U24: =IF(OR(F24="",G24=""),"",ABS(G24-F24)) | V24: =IF(A24="","",IF(AND(U24<=CONFIG!B11,H24>=CONFIG!B12),"PASS","FAIL"))
J25: SHOT-021 | K25: R1 | U25: =IF(OR(F25="",G25=""),"",ABS(G25-F25)) | V25: =IF(A25="","",IF(AND(U25<=CONFIG!B11,H25>=CONFIG!B12),"PASS","FAIL"))
J26: SHOT-022 | K26: R1 | U26: =IF(OR(F26="",G26=""),"",ABS(G26-F26)) | V26: =IF(A26="","",IF(AND(U26<=CONFIG!B11,H26>=CONFIG!B12),"PASS","FAIL"))
J27: SHOT-023 | K27: R1 | U27: =IF(OR(F27="",G27=""),"",ABS(G27-F27)) | V27: =IF(A27="","",IF(AND(U27<=CONFIG!B11,H27>=CONFIG!B12),"PASS","FAIL"))
J28: SHOT-024 | K28: R1 | U28: =IF(OR(F28="",G28=""),"",ABS(G28-F28)) | V28: =IF(A28="","",IF(AND(U28<=CONFIG!B11,H28>=CONFIG!B12),"PASS","FAIL"))
J29: SHOT-025 | K29: R1 | U29: =IF(OR(F29="",G29=""),"",ABS(G29-F29)) | V29: =IF(A29="","",IF(AND(U29<=CONFIG!B11,H29>=CONFIG!B12),"PASS","FAIL"))
J30: SHOT-026 | K30: R1 | U30: =IF(OR(F30="",G30=""),"",ABS(G30-F30)) | V30: =IF(A30="","",IF(AND(U30<=CONFIG!B11,H30>=CONFIG!B12),"PASS","FAIL"))
J31: SHOT-027 | K31: R1 | U31: =IF(OR(F31="",G31=""),"",ABS(G31-F31)) | V31: =IF(A31="","",IF(AND(U31<=CONFIG!B11,H31>=CONFIG!B12),"PASS","FAIL"))
J32: SHOT-028 | K32: R1 | U32: =IF(OR(F32="",G32=""),"",ABS(G32-F32)) | V32: =IF(A32="","",IF(AND(U32<=CONFIG!B11,H32>=CONFIG!B12),"PASS","FAIL"))
J33: SHOT-029 | K33: R1 | U33: =IF(OR(F33="",G33=""),"",ABS(G33-F33)) | V33: =IF(A33="","",IF(AND(U33<=CONFIG!B11,H33>=CONFIG!B12),"PASS","FAIL"))
J34: SHOT-030 | K34: R1 | U34: =IF(OR(F34="",G34=""),"",ABS(G34-F34)) | V34: =IF(A34="","",IF(AND(U34<=CONFIG!B11,H34>=CONFIG!B12),"PASS","FAIL"))
J35: SHOT-031 | K35: R1 | U35: =IF(OR(F35="",G35=""),"",ABS(G35-F35)) | V35: =IF(A35="","",IF(AND(U35<=CONFIG!B11,H35>=CONFIG!B12),"PASS","FAIL"))
J36: SHOT-032 | K36: R1 | U36: =IF(OR(F36="",G36=""),"",ABS(G36-F36)) | V36: =IF(A36="","",IF(AND(U36<=CONFIG!B11,H36>=CONFIG!B12),"PASS","FAIL"))
J37: SHOT-033 | K37: R1 | U37: =IF(OR(F37="",G37=""),"",ABS(G37-F37)) | V37: =IF(A37="","",IF(AND(U37<=CONFIG!B11,H37>=CONFIG!B12),"PASS","FAIL"))
J38: SHOT-034 | K38: R1 | U38: =IF(OR(F38="",G38=""),"",ABS(G38-F38)) | V38: =IF(A38="","",IF(AND(U38<=CONFIG!B11,H38>=CONFIG!B12),"PASS","FAIL"))
J39: SHOT-035 | K39: R1 | U39: =IF(OR(F39="",G39=""),"",ABS(G39-F39)) | V39: =IF(A39="","",IF(AND(U39<=CONFIG!B11,H39>=CONFIG!B12),"PASS","FAIL"))
J40: SHOT-036 | K40: R1 | U40: =IF(OR(F40="",G40=""),"",ABS(G40-F40)) | V40: =IF(A40="","",IF(AND(U40<=CONFIG!B11,H40>=CONFIG!B12),"PASS","FAIL"))
J41: SHOT-037 | K41: R1 | U41: =IF(OR(F41="",G41=""),"",ABS(G41-F41)) | V41: =IF(A41="","",IF(AND(U41<=CONFIG!B11,H41>=CONFIG!B12),"PASS","FAIL"))
...

Sheet EXPORT_SHOT_DATASET
A1: EXPORT SHOT_DATASET — CSV
A2: Exportar como CSV; #sessionId hace que el parser ignore el header.
A4: #sessionId | B4: distanceGroupId | C4: modelKind | D4: role | E4: distanceInches | F4: targetRpm | G4: measuredRpmAtFeed | H4: rpmReadyHoldMs | I4: outcome
A5: =IF(SHOT_DATASET!A5="","",SHOT_DATASET!A5) | B5: =IF(SHOT_DATASET!A5="","",SHOT_DATASET!B5) | C5: =IF(SHOT_DATASET!A5="","",SHOT_DATASET!C5) | D5: =IF(SHOT_DATASET!A5="","",SHOT_DATASET!D5) | E5: =IF(SHOT_DATASET!A5="","",SHOT_DATASET!E5) | F5: =IF(SHOT_DATASET!A5="","",SHOT_DATASET!F5) | G5: =IF(SHOT_DATASET!A5="","",SHOT_DATASET!G5) | H5: =IF(SHOT_DATASET!A5="","",SHOT_DATASET!H5) | I5: =IF(SHOT_DATASET!A5="","",SHOT_DATASET!I5)
A6: =IF(SHOT_DATASET!A6="","",SHOT_DATASET!A6) | B6: =IF(SHOT_DATASET!A6="","",SHOT_DATASET!B6) | C6: =IF(SHOT_DATASET!A6="","",SHOT_DATASET!C6) | D6: =IF(SHOT_DATASET!A6="","",SHOT_DATASET!D6) | E6: =IF(SHOT_DATASET!A6="","",SHOT_DATASET!E6) | F6: =IF(SHOT_DATASET!A6="","",SHOT_DATASET!F6) | G6: =IF(SHOT_DATASET!A6="","",SHOT_DATASET!G6) | H6: =IF(SHOT_DATASET!A6="","",SHOT_DATASET!H6) | I6: =IF(SHOT_DATASET!A6="","",SHOT_DATASET!I6)
A7: =IF(SHOT_DATASET!A7="","",SHOT_DATASET!A7) | B7: =IF(SHOT_DATASET!A7="","",SHOT_DATASET!B7) | C7: =IF(SHOT_DATASET!A7="","",SHOT_DATASET!C7) | D7: =IF(SHOT_DATASET!A7="","",SHOT_DATASET!D7) | E7: =IF(SHOT_DATASET!A7="","",SHOT_DATASET!E7) | F7: =IF(SHOT_DATASET!A7="","",SHOT_DATASET!F7) | G7: =IF(SHOT_DATASET!A7="","",SHOT_DATASET!G7) | H7: =IF(SHOT_DATASET!A7="","",SHOT_DATASET!H7) | I7: =IF(SHOT_DATASET!A7="","",SHOT_DATASET!I7)
A8: =IF(SHOT_DATASET!A8="","",SHOT_DATASET!A8) | B8: =IF(SHOT_DATASET!A8="","",SHOT_DATASET!B8) | C8: =IF(SHOT_DATASET!A8="","",SHOT_DATASET!C8) | D8: =IF(SHOT_DATASET!A8="","",SHOT_DATASET!D8) | E8: =IF(SHOT_DATASET!A8="","",SHOT_DATASET!E8) | F8: =IF(SHOT_DATASET!A8="","",SHOT_DATASET!F8) | G8: =IF(SHOT_DATASET!A8="","",SHOT_DATASET!G8) | H8: =IF(SHOT_DATASET!A8="","",SHOT_DATASET!H8) | I8: =IF(SHOT_DATASET!A8="","",SHOT_DATASET!I8)
A9: =IF(SHOT_DATASET!A9="","",SHOT_DATASET!A9) | B9: =IF(SHOT_DATASET!A9="","",SHOT_DATASET!B9) | C9: =IF(SHOT_DATASET!A9="","",SHOT_DATASET!C9) | D9: =IF(SHOT_DATASET!A9="","",SHOT_DATASET!D9) | E9: =IF(SHOT_DATASET!A9="","",SHOT_DATASET!E9) | F9: =IF(SHOT_DATASET!A9="","",SHOT_DATASET!F9) | G9: =IF(SHOT_DATASET!A9="","",SHOT_DATASET!G9) | H9: =IF(SHOT_DATASET!A9="","",SHOT_DATASET!H9) | I9: =IF(SHOT_DATASET!A9="","",SHOT_DATASET!I9)
A10: =IF(SHOT_DATASET!A10="","",SHOT_DATASET!A10) | B10: =IF(SHOT_DATASET!A10="","",SHOT_DATASET!B10) | C10: =IF(SHOT_DATASET!A10="","",SHOT_DATASET!C10) | D10: =IF(SHOT_DATASET!A10="","",SHOT_DATASET!D10) | E10: =IF(SHOT_DATASET!A10="","",SHOT_DATASET!E10) | F10: =IF(SHOT_DATASET!A10="","",SHOT_DATASET!F10) | G10: =IF(SHOT_DATASET!A10="","",SHOT_DATASET!G10) | H10: =IF(SHOT_DATASET!A10="","",SHOT_DATASET!H10) | I10: =IF(SHOT_DATASET!A10="","",SHOT_DATASET!I10)
A11: =IF(SHOT_DATASET!A11="","",SHOT_DATASET!A11) | B11: =IF(SHOT_DATASET!A11="","",SHOT_DATASET!B11) | C11: =IF(SHOT_DATASET!A11="","",SHOT_DATASET!C11) | D11: =IF(SHOT_DATASET!A11="","",SHOT_DATASET!D11) | E11: =IF(SHOT_DATASET!A11="","",SHOT_DATASET!E11) | F11: =IF(SHOT_DATASET!A11="","",SHOT_DATASET!F11) | G11: =IF(SHOT_DATASET!A11="","",SHOT_DATASET!G11) | H11: =IF(SHOT_DATASET!A11="","",SHOT_DATASET!H11) | I11: =IF(SHOT_DATASET!A11="","",SHOT_DATASET!I11)
A12: =IF(SHOT_DATASET!A12="","",SHOT_DATASET!A12) | B12: =IF(SHOT_DATASET!A12="","",SHOT_DATASET!B12) | C12: =IF(SHOT_DATASET!A12="","",SHOT_DATASET!C12) | D12: =IF(SHOT_DATASET!A12="","",SHOT_DATASET!D12) | E12: =IF(SHOT_DATASET!A12="","",SHOT_DATASET!E12) | F12: =IF(SHOT_DATASET!A12="","",SHOT_DATASET!F12) | G12: =IF(SHOT_DATASET!A12="","",SHOT_DATASET!G12) | H12: =IF(SHOT_DATASET!A12="","",SHOT_DATASET!H12) | I12: =IF(SHOT_DATASET!A12="","",SHOT_DATASET!I12)
A13: =IF(SHOT_DATASET!A13="","",SHOT_DATASET!A13) | B13: =IF(SHOT_DATASET!A13="","",SHOT_DATASET!B13) | C13: =IF(SHOT_DATASET!A13="","",SHOT_DATASET!C13) | D13: =IF(SHOT_DATASET!A13="","",SHOT_DATASET!D13) | E13: =IF(SHOT_DATASET!A13="","",SHOT_DATASET!E13) | F13: =IF(SHOT_DATASET!A13="","",SHOT_DATASET!F13) | G13: =IF(SHOT_DATASET!A13="","",SHOT_DATASET!G13) | H13: =IF(SHOT_DATASET!A13="","",SHOT_DATASET!H13) | I13: =IF(SHOT_DATASET!A13="","",SHOT_DATASET!I13)
A14: =IF(SHOT_DATASET!A14="","",SHOT_DATASET!A14) | B14: =IF(SHOT_DATASET!A14="","",SHOT_DATASET!B14) | C14: =IF(SHOT_DATASET!A14="","",SHOT_DATASET!C14) | D14: =IF(SHOT_DATASET!A14="","",SHOT_DATASET!D14) | E14: =IF(SHOT_DATASET!A14="","",SHOT_DATASET!E14) | F14: =IF(SHOT_DATASET!A14="","",SHOT_DATASET!F14) | G14: =IF(SHOT_DATASET!A14="","",SHOT_DATASET!G14) | H14: =IF(SHOT_DATASET!A14="","",SHOT_DATASET!H14) | I14: =IF(SHOT_DATASET!A14="","",SHOT_DATASET!I14)
A15: =IF(SHOT_DATASET!A15="","",SHOT_DATASET!A15) | B15: =IF(SHOT_DATASET!A15="","",SHOT_DATASET!B15) | C15: =IF(SHOT_DATASET!A15="","",SHOT_DATASET!C15) | D15: =IF(SHOT_DATASET!A15="","",SHOT_DATASET!D15) | E15: =IF(SHOT_DATASET!A15="","",SHOT_DATASET!E15) | F15: =IF(SHOT_DATASET!A15="","",SHOT_DATASET!F15) | G15: =IF(SHOT_DATASET!A15="","",SHOT_DATASET!G15) | H15: =IF(SHOT_DATASET!A15="","",SHOT_DATASET!H15) | I15: =IF(SHOT_DATASET!A15="","",SHOT_DATASET!I15)
A16: =IF(SHOT_DATASET!A16="","",SHOT_DATASET!A16) | B16: =IF(SHOT_DATASET!A16="","",SHOT_DATASET!B16) | C16: =IF(SHOT_DATASET!A16="","",SHOT_DATASET!C16) | D16: =IF(SHOT_DATASET!A16="","",SHOT_DATASET!D16) | E16: =IF(SHOT_DATASET!A16="","",SHOT_DATASET!E16) | F16: =IF(SHOT_DATASET!A16="","",SHOT_DATASET!F16) | G16: =IF(SHOT_DATASET!A16="","",SHOT_DATASET!G16) | H16: =IF(SHOT_DATASET!A16="","",SHOT_DATASET!H16) | I16: =IF(SHOT_DATASET!A16="","",SHOT_DATASET!I16)
... A64: =IF(SHOT_DATASET!A64="","",SHOT_DATASET!A64) | B64: =IF(SHOT_DATASET!A64="","",SHOT_DATASET!B64) | C64: =IF(SHOT_DATASET!A64="","",SHOT_DATASET!C64) | D64: =IF(SHOT_DATASET!A64="","",SHOT_DATASET!D64) | E64: =IF(SHOT_DATASET!A64="","",SHOT_DATASET!E64) | F64: =IF(SHOT_DATASET!A64="","",SHOT_DATASET!F64) | G64: =IF(SHOT_DATASET!A64="","",SHOT_DATASET!G64) | H64: =IF(SHOT_DATASET!A64="","",SHOT_DATASET!H64) | I64: =IF(SHOT_DATASET!A64="","",SHOT_DATASET!I64)

Sheet DASHBOARD
A1: DASHBOARD MP-03
A2: Resumen automático. No editar fórmulas.
A4: Gate | B4: Status | C4: Criterio | E4: Dataset extra | F4: Value | G4: Meaning
A5: Configuración | B5: =IF(COUNTIF(MP03_01_Config!F5:F18,"PASS")=0,"NOT_RUN",IF(COUNTIF(MP03_01_Config!F5:F18,"FAIL")+COUNTIF(MP03_01_Config!F5:F18,"ABORTED")>0,"FAIL",IF(COUNTIF(MP03_01_Config!F5:F18,"PASS")=14,"PASS","BLOCKED"))) -> NOT_RUN | C5: 14/14 items PASS | E5: Rows captured | F5: =COUNTIF(SHOT_DATASET!A5:A64,"<>") -> 0 | G5: Tiros con sessionId
A6: Lifecycle | B6: =IF(COUNTIF(MP03_02_Lifecycle!M5:M9,"PASS")=0,"NOT_RUN",IF(COUNTIF(MP03_02_Lifecycle!M5:M9,"FAIL")+COUNTIF(MP03_02_Lifecycle!M5:M9,"ABORTED")>0,"FAIL",IF(COUNTIF(MP03_02_Lifecycle!M5:M9,"PASS")=5,"PASS","BLOCKED"))) -> NOT_RUN | C6: 5/5 ciclos PASS | E6: Rows ready | F6: =COUNTIF(SHOT_DATASET!V5:V64,"PASS") -> 0 | G6: RPM gate PASS
A7: Tags | B7: =IF(COUNTA(MP03_03_Tags!C5:C44)=0,"NOT_RUN",IF(AND(COUNTIFS(MP03_03_Tags!C5:C44,20,MP03_03_Tags!E5:E44,"YES",MP03_03_Tags!I5:I44,"<="&CONFIG!B5,MP03_03_Tags!N5:N44,"YES",MP03_03_Tags!S5:S44,"YES",MP03_03_Tags!T5:T44,"VALID")>0,COUNTIFS(MP03_03_Tags!C5:C44,24,MP03_03_Tags!E5:E44,"YES",MP03_03_Tags!I5:I44,"<="&CONFIG!B5,MP03_03_Tags!N5:N44,"YES",MP03_03_Tags!S5:S44,"YES",MP03_03_Tags!T5:T44,"VALID")>0),"PASS","BLOCKED")) -> NOT_RUN | C7: IDs 20/24 con pose 3D válida/fresca | E7: Scored | F7: =COUNTIF(SHOT_DATASET!I5:I64,"SCORED") -> 0 | G7: Outcome SCORED
A8: Faults | B8: =IF(COUNTIF(MP03_04_Faults!J5:J12,"PASS")=0,"NOT_RUN",IF(COUNTIF(MP03_04_Faults!J5:J12,"FAIL")+COUNTIF(MP03_04_Faults!J5:J12,"ABORTED")>0,"FAIL",IF(COUNTIF(MP03_04_Faults!J5:J12,"PASS")=8,"PASS","BLOCKED"))) -> NOT_RUN | C8: 8/8 casos PASS | E8: Model status | F8: EXTRA / NOT BLOCKING | G8: No afecta MP-03
A9: MP-03 | B9: =IF(COUNTIF(B5:B8,"PASS")=0,"NOT_RUN",IF(COUNTIF(B5:B8,"FAIL")>0,"FAIL",IF(COUNTIF(B5:B8,"PASS")=4,"PASS","BLOCKED"))) -> NOT_RUN | C9: Todos PASS
A11: MP-03 PASS sólo autoriza abrir MP-04. Nunca autoriza movimiento o disparo.

Sheet QA
A1: TRIPLE QA DEL TEMPLATE
A2: Fallback Excel nativo autorizado; SHA final está en sidecar.
A4: CheckId | B4: Layer | C4: Check | D4: Status | E4: Evidence
A5: QA1-01 | B5: SOURCE | C5: AGENTS/docs MP-03 leídos | D5: PASS | E5: Builder manifest
A6: QA1-02 | B6: SOURCE | C6: IDs/unidades/thresholds cotejados | D6: PASS | E6: CONFIG
A7: QA1-03 | B7: SOURCE | C7: Dataset coincide con ShotDatasetCsv | D7: PASS | E7: EXPORT_SHOT_DATASET
A8: QA2-01 | B8: FORMULA | C8: Libro vacío no declara PASS | D8: PASS | E8: Fixture
A9: QA2-02 | B9: FORMULA | C9: PASS/FAIL/BLOCKED boundaries | D9: PASS | E9: Fixture
A10: QA2-03 | B10: FORMULA | C10: Sin errores de fórmula | D10: PASS | E10: Reopen scan
A11: QA2-04 | B11: SCHEMA | C11: Exports/tablas conservan columnas | D11: PASS | E11: Reopen
A12: QA3-01 | B12: ROUND_TRIP | C12: Export/reimport exitoso | D12: PASS | E12: Excel reopen
A13: QA3-02 | B13: VISUAL | C13: Todas las hojas renderizadas | D13: PASS | E13: PNG/PDF
A14: QA3-03 | B14: VISUAL | C14: Revisión humana sin defectos severos | D14: PASS | E14: Preview review
A15: QA3-04 | B15: HASH | C15: SHA-256 final guardado | D15: PASS | E15: .sha256 sidecar
